<?xml version="1.0"?>
<!-- created with Phobos 1.0.1 "Capricious Choutengan" -->
  <robot name="dimitri">

    <link name="abdomen_link">
      <inertial>
        <origin xyz="0.00124 -0.01481 -0.02927" rpy="0 0 0"/>
        <mass value="0.3"/>
        <inertia ixx="2e-05" ixy="0" ixz="0" iyy="2e-05" iyz="0" izz="2e-05"/>
      </inertial>
      <visual name="abdomen.001">
        <origin xyz="0.00335 -0.01521 -0.02919" rpy="-1.5708 1.5708 0"/>
        <geometry>
          <mesh filename="package://dimitri_description/meshes/dae/Plane.075.dae" scale="0.01 0.01 0.01"/>
        </geometry>
        <material name="BLACK"/>
      </visual>
      <collision name="abdomen.001.000">
        <origin xyz="0.00335 -0.01521 -0.02919" rpy="-1.5708 1.5708 0"/>
        <geometry>
          <mesh filename="package://dimitri_description/meshes/dae/Plane.000.dae" scale="1.0 1.0 1.0"/>
        </geometry>
      </collision>
    </link>

    <link name="abdomen_upper_link">
      <inertial>
        <origin xyz="0 0 0" rpy="0 0 0"/>
        <mass value="0.001"/>
        <inertia ixx="0.001" ixy="0" ixz="0" iyy="0.001" iyz="0" izz="0.001"/>
      </inertial>
    </link>

    <link name="base_link">
      <inertial>
        <origin xyz="0 0 -0.00353" rpy="0 0 0"/>
        <mass value="10.0"/>
        <inertia ixx="4e-05" ixy="0" ixz="0" iyy="4e-05" iyz="0" izz="5e-05"/>
      </inertial>
      <visual name="base">
        <origin xyz="0.0054 0 -0.00597" rpy="0 0 0"/>
        <geometry>
          <mesh filename="package://dimitri_description/meshes/dae/Cube.054.dae" scale="0.01 0.01 0.01"/>
        </geometry>
        <material name="BLACK"/>
      </visual>
      <collision name="base.000">
        <origin xyz="0.0054 0 -0.00597" rpy="0 0 0"/>
        <geometry>
          <mesh filename="package://dimitri_description/meshes/dae/Cube.000.dae" scale="1.0 1.0 1.0"/>
        </geometry>
      </collision>
    </link>

    <link name="camera_link">
      <inertial>
        <origin xyz="0 0 0" rpy="0 0 0"/>
        <mass value="0.001"/>
        <inertia ixx="0.001" ixy="0" ixz="0" iyy="0.001" iyz="0" izz="0.001"/>
      </inertial>
    </link>

    <link name="head_link">
      <inertial>
        <origin xyz="-0.01791 0.00093 0.00244" rpy="0 0 0"/>
        <mass value="0.6"/>
        <inertia ixx="0.00605" ixy="0.0001" ixz="-0.00146" iyy="0.00654" iyz="4e-05" izz="0.00255"/>
      </inertial>
      <visual name="head">
        <origin xyz="-0.01791 0.00093 0.00244" rpy="0 1.5708 0"/>
        <geometry>
          <mesh filename="package://dimitri_description/meshes/dae/Plane.078.dae" scale="0.001 0.001 0.001"/>
        </geometry>
        <material name="BLACK"/>
      </visual>
      <collision name="head.000">
        <origin xyz="-0.01791 0.00093 0.00244" rpy="0 1.5708 0"/>
        <geometry>
          <mesh filename="package://dimitri_description/meshes/dae/Plane.003.dae" scale="1.0 1.0 1.0"/>
        </geometry>
      </collision>
    </link>

    <link name="left_back_gripper_link">
      <inertial>
        <origin xyz="-0.00222 0.02277 -0.00089" rpy="0 0 0"/>
        <mass value="0.1"/>
        <inertia ixx="2e-05" ixy="0" ixz="0" iyy="2e-05" iyz="0" izz="2e-05"/>
      </inertial>
      <visual name="left_back_gripper">
        <origin xyz="-0.0059 0.0247 -0.00089" rpy="0 -1.5708 0"/>
        <geometry>
          <mesh filename="package://dimitri_description/meshes/dae/Cube.008.dae" scale="-0.01 -0.01 -0.01"/>
        </geometry>
        <material name="BLACK"/>
      </visual>
      <collision name="left_back_gripper.000">
        <origin xyz="-0.0059 0.0247 -0.00089" rpy="0 -1.5708 0"/>
        <geometry>
          <mesh filename="package://dimitri_description/meshes/dae/Cube.005.dae" scale="1.0 1.0 1.0"/>
        </geometry>
      </collision>
    </link>

    <link name="left_front_gripper">
      <inertial>
        <origin xyz="-0.0012 0.02088 -0.00104" rpy="0 0 0"/>
        <mass value="0.1"/>
        <inertia ixx="2e-05" ixy="0" ixz="0" iyy="2e-05" iyz="0" izz="2e-05"/>
      </inertial>
      <visual name="left_front_gripper.001">
        <origin xyz="0.00058 0.01916 -0.00104" rpy="0 -1.5708 0"/>
        <geometry>
          <mesh filename="package://dimitri_description/meshes/dae/Cube.010.dae" scale="-0.01 -0.01 -0.01"/>
        </geometry>
        <material name="BLACK"/>
      </visual>
      <collision name="left_front_gripper.001.000">
        <origin xyz="0.00058 0.01916 -0.00104" rpy="0 -1.5708 0"/>
        <geometry>
          <mesh filename="package://dimitri_description/meshes/dae/Cube.004.dae" scale="1.0 1.0 1.0"/>
        </geometry>
      </collision>
    </link>

    <link name="left_hand_link">
      <inertial>
        <origin xyz="0 0.0301 0" rpy="0 0 0"/>
        <mass value="0.5"/>
        <inertia ixx="2e-05" ixy="0" ixz="0" iyy="2e-05" iyz="0" izz="2e-05"/>
      </inertial>
      <visual name="left_hand">
        <origin xyz="-0.00076 0.029 -0.0005" rpy="-1.5708 0 0"/>
        <geometry>
          <mesh filename="package://dimitri_description/meshes/dae/Plane.020.dae" scale="-0.01 -0.01 -0.01"/>
        </geometry>
        <material name="BLACK"/>
      </visual>
      <collision name="left_hand.000">
        <origin xyz="-0.00076 0.029 -0.0005" rpy="-1.5708 0 0"/>
        <geometry>
          <mesh filename="package://dimitri_description/meshes/dae/Plane.007.dae" scale="1.0 1.0 1.0"/>
        </geometry>
      </collision>
    </link>

    <link name="left_shoulder_link">
      <inertial>
        <origin xyz="0 0 -0.00553" rpy="0 0 0"/>
        <mass value="0.1"/>
        <inertia ixx="2e-05" ixy="0" ixz="0" iyy="2e-05" iyz="0" izz="2e-05"/>
      </inertial>
      <visual name="left_shoulder">
        <origin xyz="-0.00116 0.00236 -0.00594" rpy="-3.14159 0 0"/>
        <geometry>
          <mesh filename="package://dimitri_description/meshes/dae/Plane.028.dae" scale="-0.01 -0.01 -0.01"/>
        </geometry>
        <material name="BLACK"/>
      </visual>
      <collision name="left_shoulder.000">
        <origin xyz="-0.00116 0.00236 -0.00594" rpy="-3.14159 0 0"/>
        <geometry>
          <mesh filename="package://dimitri_description/meshes/dae/Plane.004.dae" scale="1.0 1.0 1.0"/>
        </geometry>
      </collision>
    </link>

    <link name="left_under_arm_link">
      <inertial>
        <origin xyz="0.06695 0 0" rpy="0 0 0"/>
        <mass value="0.3"/>
        <inertia ixx="2e-05" ixy="0" ixz="0" iyy="2e-05" iyz="0" izz="2e-05"/>
      </inertial>
      <visual name="left_under">
        <origin xyz="0.06803 -0.00034 0.00114" rpy="1.5708 0 0"/>
        <geometry>
          <mesh filename="package://dimitri_description/meshes/dae/Cube.014.dae" scale="-0.01 -0.01 -0.01"/>
        </geometry>
        <material name="BLACK"/>
      </visual>
      <collision name="left_under.000">
        <origin xyz="0.06803 -0.00034 0.00114" rpy="1.5708 0 0"/>
        <geometry>
          <mesh filename="package://dimitri_description/meshes/dae/Cube.003.dae" scale="1.0 1.0 1.0"/>
        </geometry>
      </collision>
    </link>

    <link name="left_upper_arm_link">
      <inertial>
        <origin xyz="0 0.01708 -0.01838" rpy="0 0 0"/>
        <mass value="0.3"/>
        <inertia ixx="2e-05" ixy="0" ixz="0" iyy="2e-05" iyz="0" izz="2e-05"/>
      </inertial>
      <visual name="left_upper">
        <origin xyz="0.00012 0.01818 -0.01904" rpy="-1.5708 0 0"/>
        <geometry>
          <mesh filename="package://dimitri_description/meshes/dae/Plane.031.dae" scale="-0.01 -0.01 -0.01"/>
        </geometry>
        <material name="BLACK"/>
      </visual>
      <collision name="left_upper.000">
        <origin xyz="0.00012 0.01818 -0.01904" rpy="-1.5708 0 0"/>
        <geometry>
          <mesh filename="package://dimitri_description/meshes/dae/Plane.005.dae" scale="1.0 1.0 1.0"/>
        </geometry>
      </collision>
    </link>

    <link name="left_wrist_link">
      <inertial>
        <origin xyz="0 0 0.002" rpy="0 0 0"/>
        <mass value="0.1"/>
        <inertia ixx="2e-05" ixy="0" ixz="0" iyy="2e-05" iyz="0" izz="2e-05"/>
      </inertial>
      <visual name="left_wrist">
        <origin xyz="0 0 -0.0013" rpy="0 0 3.14159"/>
        <geometry>
          <mesh filename="package://dimitri_description/meshes/dae/Plane.021.dae" scale="-0.01 -0.01 -0.01"/>
        </geometry>
        <material name="BLACK"/>
      </visual>
      <collision name="left_wrist.000">
        <origin xyz="0 0 -0.0013" rpy="0 0 3.14159"/>
        <geometry>
          <mesh filename="package://dimitri_description/meshes/dae/Plane.006.dae" scale="1.0 1.0 1.0"/>
        </geometry>
      </collision>
    </link>

    <link name="neck_link">
      <inertial>
        <origin xyz="0.00085 0 0.05247" rpy="0 0 0"/>
        <mass value="0.2"/>
        <inertia ixx="2e-05" ixy="0" ixz="0" iyy="2e-05" iyz="0" izz="2e-05"/>
      </inertial>
      <visual name="neck">
        <origin xyz="0.00085 0.00022 0.05252" rpy="0 0 0"/>
        <geometry>
          <mesh filename="package://dimitri_description/meshes/dae/Cube.055.dae" scale="0.01 0.01 0.01"/>
        </geometry>
        <material name="BLACK"/>
      </visual>
      <collision name="neck.000">
        <origin xyz="0.00085 0.00022 0.05252" rpy="0 0 0"/>
        <geometry>
          <mesh filename="package://dimitri_description/meshes/dae/Cube.002.dae" scale="1.0 1.0 1.0"/>
        </geometry>
      </collision>
    </link>

    <link name="right_back_gripper_link">
      <inertial>
        <origin xyz="-0.00056 -0.02143 -0.00105" rpy="0 0 0"/>
        <mass value="0.1"/>
        <inertia ixx="2e-05" ixy="0" ixz="0" iyy="2e-05" iyz="0" izz="2e-05"/>
      </inertial>
      <visual name="right_back_gripper">
        <origin xyz="-0.00034 -0.0205 -0.00105" rpy="0 -1.5708 0"/>
        <geometry>
          <mesh filename="package://dimitri_description/meshes/dae/Cube.040.dae" scale="0.01 0.01 0.01"/>
        </geometry>
        <material name="BLACK"/>
      </visual>
      <collision name="right_back_gripper.000">
        <origin xyz="-0.00034 -0.0205 -0.00105" rpy="0 -1.5708 0"/>
        <geometry>
          <mesh filename="package://dimitri_description/meshes/dae/Cube.009.dae" scale="1.0 1.0 1.0"/>
        </geometry>
      </collision>
    </link>

    <link name="right_front_gripper_link">
      <inertial>
        <origin xyz="0 -0.02071 0" rpy="0 0 0"/>
        <mass value="0.1"/>
        <inertia ixx="2e-05" ixy="0" ixz="0" iyy="2e-05" iyz="0" izz="2e-05"/>
      </inertial>
      <visual name="right_front_gripper">
        <origin xyz="-0.00188 -0.02174 0" rpy="0 -1.5708 0"/>
        <geometry>
          <mesh filename="package://dimitri_description/meshes/dae/Cube.039.dae" scale="0.01 0.01 0.01"/>
        </geometry>
        <material name="BLACK"/>
      </visual>
      <collision name="right_front_gripper.000">
        <origin xyz="-0.00188 -0.02174 0" rpy="0 -1.5708 0"/>
        <geometry>
          <mesh filename="package://dimitri_description/meshes/dae/Cube.011.dae" scale="1.0 1.0 1.0"/>
        </geometry>
      </collision>
    </link>

    <link name="right_hand_link">
      <inertial>
        <origin xyz="0 -0.03301 0.0001" rpy="0 0 0"/>
        <mass value="0.5"/>
        <inertia ixx="2e-05" ixy="0" ixz="0" iyy="2e-05" iyz="0" izz="2e-05"/>
      </inertial>
      <visual name="right_hand">
        <origin xyz="0.00076 -0.03372 -0.00037" rpy="-1.5708 0 0"/>
        <geometry>
          <mesh filename="package://dimitri_description/meshes/dae/Plane.045.dae" scale="0.01 0.01 0.01"/>
        </geometry>
        <material name="BLACK"/>
      </visual>
      <collision name="right_hand.000">
        <origin xyz="0.00076 -0.03372 -0.00037" rpy="-1.5708 0 0"/>
        <geometry>
          <mesh filename="package://dimitri_description/meshes/dae/Plane.011.dae" scale="1.0 1.0 1.0"/>
        </geometry>
      </collision>
    </link>

    <link name="right_shoulder_link">
      <inertial>
        <origin xyz="0 0 0" rpy="0 0 0"/>
        <mass value="0.1"/>
        <inertia ixx="2e-05" ixy="0" ixz="0" iyy="2e-05" iyz="0" izz="2e-05"/>
      </inertial>
      <visual name="right_shoulder">
        <origin xyz="0 0 0.00169" rpy="0 -3.14159 0"/>
        <geometry>
          <mesh filename="package://dimitri_description/meshes/dae/Plane.002.dae" scale="0.01 0.01 0.01"/>
        </geometry>
        <material name="BLACK"/>
      </visual>
      <collision name="right_shoulder.000">
        <origin xyz="0 0 0.00169" rpy="0 -3.14159 0"/>
        <geometry>
          <mesh filename="package://dimitri_description/meshes/dae/Plane.008.dae" scale="1.0 1.0 1.0"/>
        </geometry>
      </collision>
    </link>

    <link name="right_under_arm_link">
      <inertial>
        <origin xyz="-4e-05 -0.0675 -0.00761" rpy="0 0 0"/>
        <mass value="0.3"/>
        <inertia ixx="2e-05" ixy="0" ixz="0" iyy="2e-05" iyz="0" izz="2e-05"/>
      </inertial>
      <visual name="right_under">
        <origin xyz="-0.00038 -0.06842 -0.00631" rpy="1.5708 0 1.5708"/>
        <geometry>
          <mesh filename="package://dimitri_description/meshes/dae/Cube.006.dae" scale="0.01 0.01 0.01"/>
        </geometry>
        <material name="BLACK"/>
      </visual>
      <collision name="right_under.000">
        <origin xyz="-0.00038 -0.06842 -0.00631" rpy="1.5708 0 1.5708"/>
        <geometry>
          <mesh filename="package://dimitri_description/meshes/dae/Cube.007.dae" scale="1.0 1.0 1.0"/>
        </geometry>
      </collision>
    </link>

    <link name="right_upper_arm_link">
      <inertial>
        <origin xyz="0 -0.01507 0" rpy="0 0 0"/>
        <mass value="0.3"/>
        <inertia ixx="2e-05" ixy="0" ixz="0" iyy="2e-05" iyz="0" izz="2e-05"/>
      </inertial>
      <visual name="right_upper">
        <origin xyz="0.00038 -0.0168 0.00055" rpy="-1.5708 0 0"/>
        <geometry>
          <mesh filename="package://dimitri_description/meshes/dae/Plane.037.dae" scale="0.01 0.01 0.01"/>
        </geometry>
        <material name="BLACK"/>
      </visual>
      <collision name="right_upper.000">
        <origin xyz="0.00038 -0.0168 0.00055" rpy="-1.5708 0 0"/>
        <geometry>
          <mesh filename="package://dimitri_description/meshes/dae/Plane.009.dae" scale="1.0 1.0 1.0"/>
        </geometry>
      </collision>
    </link>

    <link name="right_wrist_link">
      <inertial>
        <origin xyz="0 0.00233 0.00651" rpy="0 0 0"/>
        <mass value="0.1"/>
        <inertia ixx="2e-05" ixy="0" ixz="0" iyy="2e-05" iyz="0" izz="2e-05"/>
      </inertial>
      <visual name="rigth_wrist">
        <origin xyz="0 0.00233 0.00728" rpy="0 0 0"/>
        <geometry>
          <mesh filename="package://dimitri_description/meshes/dae/Plane.044.dae" scale="0.01 0.01 0.01"/>
        </geometry>
        <material name="BLACK"/>
      </visual>
      <collision name="rigth_wrist.000">
        <origin xyz="0 0.00233 0.00728" rpy="0 0 0"/>
        <geometry>
          <mesh filename="package://dimitri_description/meshes/dae/Plane.010.dae" scale="1.0 1.0 1.0"/>
        </geometry>
      </collision>
    </link>

    <link name="root">
      <inertial>
        <origin xyz="0 0 0" rpy="0 0 0"/>
        <mass value="0.001"/>
        <inertia ixx="0.001" ixy="0" ixz="0" iyy="0.001" iyz="0" izz="0.001"/>
      </inertial>
    </link>

    <link name="torso_link">
      <inertial>
        <origin xyz="0.00794 0.00104 0.00678" rpy="0 0 0"/>
        <mass value="1.0"/>
        <inertia ixx="0.00523" ixy="-4e-05" ixz="0" iyy="0.00257" iyz="0" izz="0.00507"/>
      </inertial>
      <visual name="torso">
        <origin xyz="0.00794 0.00104 0.00678" rpy="0 0 0"/>
        <geometry>
          <mesh filename="package://dimitri_description/meshes/dae/Cube.001.dae" scale="1.0 1.0 1.0"/>
        </geometry>
        <material name="BLACK"/>
      </visual>
      <collision name="torso.000">
        <origin xyz="0.00794 0.00104 0.00678" rpy="0 0 0"/>
        <geometry>
          <mesh filename="package://dimitri_description/meshes/dae/Cube.001.dae" scale="1.0 1.0 1.0"/>
        </geometry>
      </collision>
    </link>

    <link name="torso_under_link">
      <inertial>
        <origin xyz="-0.00794 -0.00136 0.00241" rpy="0 0 0"/>
        <mass value="0.3"/>
        <inertia ixx="2e-05" ixy="0" ixz="0" iyy="2e-05" iyz="0" izz="2e-05"/>
      </inertial>
      <visual name="abdomen_upper">
        <origin xyz="-0.0076 -0.00381 0.00466" rpy="0 1.5708 0"/>
        <geometry>
          <mesh filename="package://dimitri_description/meshes/dae/Plane.073.dae" scale="0.01 0.01 0.01"/>
        </geometry>
        <material name="BLACK"/>
      </visual>
      <collision name="abdomen_upper.000">
        <origin xyz="-0.0076 -0.00381 0.00466" rpy="0 1.5708 0"/>
        <geometry>
          <mesh filename="package://dimitri_description/meshes/dae/Plane.001.dae" scale="1.0 1.0 1.0"/>
        </geometry>
      </collision>
    </link>

    <joint name="abdomen_link" type="revolute">
      <origin xyz="-0.01876 0.02798 0.43095" rpy="-1.5708 0 0"/>
      <parent link="base_link"/>
      <child link="abdomen_link"/>
      <axis xyz="0 0 1.0"/>
      <limit lower="-0.45379" upper="0.45379" effort="10.0" velocity="0.03491"/>
    </joint>

    <joint name="abdomen_upper_link" type="revolute">
      <origin xyz="0.01917 0.00123 -0.02722" rpy="1.5708 0 1.5708"/>
      <parent link="abdomen_link"/>
      <child link="abdomen_upper_link"/>
      <axis xyz="0 0 1.0"/>
      <limit lower="-0.45379" upper="0.45379" effort="10.0" velocity="0.03491"/>
    </joint>

    <joint name="base_link" type="fixed">
      <origin xyz="0 0 0.12353" rpy="0 0 0"/>
      <parent link="root"/>
      <child link="base_link"/>
    </joint>

    <joint name="camera_link" type="fixed">
      <origin xyz="-0.0085 -0.11925 0.00567" rpy="1.5708 0 0.68865"/>
      <parent link="head_link"/>
      <child link="camera_link"/>
    </joint>

    <joint name="head_link" type="revolute">
      <origin xyz="0.00084 -0.0004 0.07009" rpy="0 1.5708 0"/>
      <parent link="neck_link"/>
      <child link="head_link"/>
      <axis xyz="0 0 1.0"/>
      <limit lower="-0.34907" upper="0.2618" effort="10.0" velocity="0.03491"/>
    </joint>

    <joint name="left_back_gripper_link" type="revolute">
      <origin xyz="0.01536 0.09638 -0.00157" rpy="0 0 -1.5708"/>
      <parent link="left_hand_link"/>
      <child link="left_back_gripper_link"/>
      <axis xyz="0 0 1.0"/>
      <limit lower="0" upper="1.309" effort="10.0" velocity="0.03491"/>
    </joint>

    <joint name="left_front_gripper" type="revolute">
      <origin xyz="-0.01893 0.09638 0.00011" rpy="3.14159 0 -1.5708"/>
      <parent link="left_hand_link"/>
      <child link="left_front_gripper"/>
      <axis xyz="0 0 1.0"/>
      <limit lower="0" upper="1.309" effort="10.0" velocity="0.03491"/>
    </joint>

    <joint name="left_hand_link" type="revolute">
      <origin xyz="-0.00012 0.001 -0.02198" rpy="-1.5708 0 0"/>
      <parent link="left_wrist_link"/>
      <child link="left_hand_link"/>
      <axis xyz="0 0 1.0"/>
      <limit lower="0" upper="1.5708" effort="10.0" velocity="0.03491"/>
    </joint>

    <joint name="left_shoulder_link" type="revolute">
      <origin xyz="0.01176 0.11735 0.01717" rpy="1.5708 -1.5708 0"/>
      <parent link="torso_link"/>
      <child link="left_shoulder_link"/>
      <axis xyz="0 0 1.0"/>
      <limit lower="-0.5236" upper="2.61799" effort="10.0" velocity="0.03491"/>
    </joint>

    <joint name="left_under_arm_link" type="revolute">
      <origin xyz="0.01456 0.11997 -0.0184" rpy="1.5708 0 1.5708"/>
      <parent link="left_upper_arm_link"/>
      <child link="left_under_arm_link"/>
      <axis xyz="0 0 1.0"/>
      <limit lower="0" upper="1.5708" effort="10.0" velocity="0.03491"/>
    </joint>

    <joint name="left_upper_arm_link" type="revolute">
      <origin xyz="0.00078 -0.01161 -0.02742" rpy="1.5708 -1.5708 0"/>
      <parent link="left_shoulder_link"/>
      <child link="left_upper_arm_link"/>
      <axis xyz="0 0 1.0"/>
      <limit lower="0" upper="2.26893" effort="10.0" velocity="0.03491"/>
    </joint>

    <joint name="left_wrist_link" type="revolute">
      <origin xyz="0.12993 0.00068 -0.00159" rpy="1.5708 0 -1.5708"/>
      <parent link="left_under_arm_link"/>
      <child link="left_wrist_link"/>
      <axis xyz="0 0 1.0"/>
      <limit lower="0" upper="4.71239" effort="10.0" velocity="0.03491"/>
    </joint>

    <joint name="neck_link" type="revolute">
      <origin xyz="-0.00148 0.0012 0.06885" rpy="0 0 1.5708"/>
      <parent link="torso_link"/>
      <child link="neck_link"/>
      <axis xyz="0 0 1.0"/>
      <limit lower="-1.0472" upper="1.0472" effort="10.0" velocity="0.03491"/>
    </joint>

    <joint name="right_back_gripper_link" type="revolute">
      <origin xyz="-0.01669 -0.09929 0.00166" rpy="0 0 -1.5708"/>
      <parent link="right_hand_link"/>
      <child link="right_back_gripper_link"/>
      <axis xyz="0 0 1.0"/>
      <limit lower="0" upper="1.309" effort="10.0" velocity="0.03491"/>
    </joint>

    <joint name="right_front_gripper_link" type="revolute">
      <origin xyz="0.0191 -0.09917 0.00014" rpy="-3.14159 0 -1.5708"/>
      <parent link="right_hand_link"/>
      <child link="right_front_gripper_link"/>
      <axis xyz="0 0 1.0"/>
      <limit lower="0" upper="1.309" effort="10.0" velocity="0.03491"/>
    </joint>

    <joint name="right_hand_link" type="revolute">
      <origin xyz="0.00012 0.00225 0.02795" rpy="-1.5708 0 0"/>
      <parent link="right_wrist_link"/>
      <child link="right_hand_link"/>
      <axis xyz="0 0 1.0"/>
      <limit lower="0" upper="1.5708" effort="10.0" velocity="0.03491"/>
    </joint>

    <joint name="right_shoulder_link" type="revolute">
      <origin xyz="0.01176 -0.12018 0.01717" rpy="1.5708 1.5708 0"/>
      <parent link="torso_link"/>
      <child link="right_shoulder_link"/>
      <axis xyz="0 0 1.0"/>
      <limit lower="-0.5236" upper="2.61799" effort="10.0" velocity="0.03491"/>
    </joint>

    <joint name="right_under_arm_link" type="revolute">
      <origin xyz="-0.00738 -0.11596 -5e-05" rpy="0 1.5708 0"/>
      <parent link="right_upper_arm_link"/>
      <child link="right_under_arm_link"/>
      <axis xyz="0 0 1.0"/>
      <limit lower="0" upper="1.5708" effort="10.0" velocity="0.03491"/>
    </joint>

    <joint name="right_upper_arm_link" type="revolute">
      <origin xyz="0.0001 -0.00679 0.02608" rpy="1.5708 -1.5708 0"/>
      <parent link="right_shoulder_link"/>
      <child link="right_upper_arm_link"/>
      <axis xyz="0 0 1.0"/>
      <limit lower="0" upper="2.61799" effort="10.0" velocity="0.03491"/>
    </joint>

    <joint name="right_wrist_link" type="revolute">
      <origin xyz="0.00063 -0.12268 -0.00602" rpy="1.5708 0 0"/>
      <parent link="right_under_arm_link"/>
      <child link="right_wrist_link"/>
      <axis xyz="0 0 1.0"/>
      <limit lower="0" upper="4.71239" effort="10.0" velocity="0.03491"/>
    </joint>

    <joint name="torso_link" type="fixed">
      <origin xyz="0.00836 -0.00182 0.08279" rpy="0 0 0"/>
      <parent link="torso_under_link"/>
      <child link="torso_link"/>
    </joint>

    <joint name="torso_under_link" type="fixed">
      <origin xyz="-0.0901 0.0006 -0.04379" rpy="0 -1.5708 0"/>
      <parent link="abdomen_upper_link"/>
      <child link="torso_under_link"/>
    </joint>

  <transmission name="tran1">
    <type>transmission_interface/SimpleTransmission</type>
    <joint name="abdomen_link">
      <hardwareInterface>hardware_interface/EffortJointInterface</hardwareInterface>
    </joint>
    <actuator name="motor1">
      <hardwareInterface>hardware_interface/EffortJointInterface</hardwareInterface>
      <mechanicalReduction>1</mechanicalReduction>
    </actuator>
  </transmission>

  <transmission name="tran2">
    <type>transmission_interface/SimpleTransmission</type>
    <joint name="abdomen_upper_link">
      <hardwareInterface>hardware_interface/EffortJointInterface</hardwareInterface>
    </joint>
    <actuator name="motor2">
      <hardwareInterface>hardware_interface/EffortJointInterface</hardwareInterface>
      <mechanicalReduction>1</mechanicalReduction>
    </actuator>
  </transmission>

  <transmission name="tran3">
    <type>transmission_interface/SimpleTransmission</type>
    <joint name="head_link">
      <hardwareInterface>hardware_interface/EffortJointInterface</hardwareInterface>
    </joint>
    <actuator name="motor3">
      <hardwareInterface>hardware_interface/EffortJointInterface</hardwareInterface>
      <mechanicalReduction>1</mechanicalReduction>
    </actuator>
  </transmission>

  <transmission name="tran4">
    <type>transmission_interface/SimpleTransmission</type>
    <joint name="left_back_gripper_link">
      <hardwareInterface>hardware_interface/EffortJointInterface</hardwareInterface>
    </joint>
    <actuator name="motor4">
      <hardwareInterface>hardware_interface/EffortJointInterface</hardwareInterface>
      <mechanicalReduction>1</mechanicalReduction>
    </actuator>
  </transmission>

  <transmission name="tran5">
    <type>transmission_interface/SimpleTransmission</type>
    <joint name="left_front_gripper">
      <hardwareInterface>hardware_interface/EffortJointInterface</hardwareInterface>
    </joint>
    <actuator name="motor5">
      <hardwareInterface>hardware_interface/EffortJointInterface</hardwareInterface>
      <mechanicalReduction>1</mechanicalReduction>
    </actuator>
  </transmission>

  <transmission name="tran6">
    <type>transmission_interface/SimpleTransmission</type>
    <joint name="left_hand_link">
      <hardwareInterface>hardware_interface/EffortJointInterface</hardwareInterface>
    </joint>
    <actuator name="motor6">
      <hardwareInterface>hardware_interface/EffortJointInterface</hardwareInterface>
      <mechanicalReduction>1</mechanicalReduction>
    </actuator>
  </transmission>

  <transmission name="tran7">
    <type>transmission_interface/SimpleTransmission</type>
    <joint name="left_shoulder_link">
      <hardwareInterface>hardware_interface/EffortJointInterface</hardwareInterface>
    </joint>
    <actuator name="motor7">
      <hardwareInterface>hardware_interface/EffortJointInterface</hardwareInterface>
      <mechanicalReduction>1</mechanicalReduction>
    </actuator>
  </transmission>

  <transmission name="tran8">
    <type>transmission_interface/SimpleTransmission</type>
    <joint name="left_under_arm_link">
      <hardwareInterface>hardware_interface/EffortJointInterface</hardwareInterface>
    </joint>
    <actuator name="motor8">
      <hardwareInterface>hardware_interface/EffortJointInterface</hardwareInterface>
      <mechanicalReduction>1</mechanicalReduction>
    </actuator>
  </transmission>

  <transmission name="tran9">
    <type>transmission_interface/SimpleTransmission</type>
    <joint name="left_upper_arm_link">
      <hardwareInterface>hardware_interface/EffortJointInterface</hardwareInterface>
    </joint>
    <actuator name="motor9">
      <hardwareInterface>hardware_interface/EffortJointInterface</hardwareInterface>
      <mechanicalReduction>1</mechanicalReduction>
    </actuator>
  </transmission>

  <transmission name="tran10">
    <type>transmission_interface/SimpleTransmission</type>
    <joint name="left_wrist_link">
      <hardwareInterface>hardware_interface/EffortJointInterface</hardwareInterface>
    </joint>
    <actuator name="motor10">
      <hardwareInterface>hardware_interface/EffortJointInterface</hardwareInterface>
      <mechanicalReduction>1</mechanicalReduction>
    </actuator>
  </transmission>

  <transmission name="tran11">
    <type>transmission_interface/SimpleTransmission</type>
    <joint name="neck_link">
      <hardwareInterface>hardware_interface/EffortJointInterface</hardwareInterface>
    </joint>
    <actuator name="motor11">
      <hardwareInterface>hardware_interface/EffortJointInterface</hardwareInterface>
      <mechanicalReduction>1</mechanicalReduction>
    </actuator>
  </transmission>

  <transmission name="tran12">
    <type>transmission_interface/SimpleTransmission</type>
    <joint name="right_back_gripper_link">
      <hardwareInterface>hardware_interface/EffortJointInterface</hardwareInterface>
    </joint>
    <actuator name="motor12">
      <hardwareInterface>hardware_interface/EffortJointInterface</hardwareInterface>
      <mechanicalReduction>1</mechanicalReduction>
    </actuator>
  </transmission>

  <transmission name="tran13">
    <type>transmission_interface/SimpleTransmission</type>
    <joint name="right_front_gripper_link">
      <hardwareInterface>hardware_interface/EffortJointInterface</hardwareInterface>
    </joint>
    <actuator name="motor13">
      <hardwareInterface>hardware_interface/EffortJointInterface</hardwareInterface>
      <mechanicalReduction>1</mechanicalReduction>
    </actuator>
  </transmission>

  <transmission name="tran14">
    <type>transmission_interface/SimpleTransmission</type>
    <joint name="right_hand_link">
      <hardwareInterface>hardware_interface/EffortJointInterface</hardwareInterface>
    </joint>
    <actuator name="motor14">
      <hardwareInterface>hardware_interface/EffortJointInterface</hardwareInterface>
      <mechanicalReduction>1</mechanicalReduction>
    </actuator>
  </transmission>

  <transmission name="tran15">
    <type>transmission_interface/SimpleTransmission</type>
    <joint name="right_shoulder_link">
      <hardwareInterface>hardware_interface/EffortJointInterface</hardwareInterface>
    </joint>
    <actuator name="motor15">
      <hardwareInterface>hardware_interface/EffortJointInterface</hardwareInterface>
      <mechanicalReduction>1</mechanicalReduction>
    </actuator>
  </transmission>

  <transmission name="tran16">
    <type>transmission_interface/SimpleTransmission</type>
    <joint name="right_under_arm_link">
      <hardwareInterface>hardware_interface/EffortJointInterface</hardwareInterface>
    </joint>
    <actuator name="motor16">
      <hardwareInterface>hardware_interface/EffortJointInterface</hardwareInterface>
      <mechanicalReduction>1</mechanicalReduction>
    </actuator>
  </transmission>

  <transmission name="tran17">
    <type>transmission_interface/SimpleTransmission</type>
    <joint name="right_upper_arm_link">
      <hardwareInterface>hardware_interface/EffortJointInterface</hardwareInterface>
    </joint>
    <actuator name="motor17">
      <hardwareInterface>hardware_interface/EffortJointInterface</hardwareInterface>
      <mechanicalReduction>1</mechanicalReduction>
    </actuator>
  </transmission>

  <transmission name="tran18">
    <type>transmission_interface/SimpleTransmission</type>
    <joint name="right_wrist_link">
      <hardwareInterface>hardware_interface/EffortJointInterface</hardwareInterface>
    </joint>
    <actuator name="motor18">
      <hardwareInterface>hardware_interface/EffortJointInterface</hardwareInterface>
      <mechanicalReduction>1</mechanicalReduction>
    </actuator>
  </transmission>


  <gazebo>
    <plugin name="gazebo_ros_control" filename="libgazebo_ros_control.so">
      <robotNamespace>/dimitri</robotNamespace>
    </plugin>
  </gazebo>

  <gazebo reference="camera_link">
    <sensor type="camera" name="camera1">
      <update_rate>30.0</update_rate>
      <camera name="head">
        <horizontal_fov>1.3962634</horizontal_fov>
        <image>
          <width>800</width>
          <height>800</height>
          <format>R8G8B8</format>
        </image>
        <clip>
          <near>0.02</near>
          <far>300</far>
        </clip>
        <noise>
          <type>gaussian</type>
          <!-- Noise is sampled independently per pixel on each frame.
               That pixel's noise value is added to each of its color
               channels, which at that point lie in the range [0,1]. -->
          <mean>0.0</mean>
          <stddev>0.007</stddev>
        </noise>
      </camera>
      <plugin name="camera_controller" filename="libgazebo_ros_camera.so">
        <alwaysOn>true</alwaysOn>
        <updateRate>0.0</updateRate>
        <cameraName>dimitri/camera1</cameraName>
        <imageTopicName>image_raw</imageTopicName>
        <cameraInfoTopicName>camera_info</cameraInfoTopicName>
        <frameName>camera_link</frameName>
        <hackBaseline>0.07</hackBaseline>
        <distortionK1>0.0</distortionK1>
        <distortionK2>0.0</distortionK2>
        <distortionK3>0.0</distortionK3>
        <distortionT1>0.0</distortionT1>
        <distortionT2>0.0</distortionT2>
      </plugin>
    </sensor>
  </gazebo>

  <material name="BLACK">
    <color rgba="0.00291 0.00291 0.00291 1.0"/>
  </material>

  </robot>
